Workbook

Sheet บันทึกผล
A1: รหัสกิจกรรม | B1: แผนหลัก | C1: แผนงานย่อย | D1: รหัส | E1: ชื่อกิจกรรม | F1: ผู้รับผิดชอบ | G1: เป้า ม.ค. | H1: เป้า ก.พ. | I1: เป้า มี.ค. | J1: เป้า เม.ย. | K1: เป้า พ.ค. | L1: เป้า มิ.ย. | M1: เป้า ก.ค. | N1: เป้า ส.ค. | O1: เป้า ก.ย. | P1: เป้า ต.ค. | Q1: เป้า พ.ย. | R1: เป้า ธ.ค. | S1: ผล ม.ค. | T1: ผล ก.พ. | U1: ผล มี.ค. | V1: ผล เม.ย. | W1: ผล พ.ค. | X1: ผล มิ.ย. | Y1: ผล ก.ค. | Z1: ผล ส.ค. | AA1: ผล ก.ย. | AB1: ผล ต.ค. | AC1: ผล พ.ย. | AD1: ผล ธ.ค. | AE1: รายละเอียดการดำเนินการ (ล่าสุด) | AF1: ปัญหาอุปสรรค | AG1: ผู้รายงาน | AH1: ถ่วงน้ำหนัก(%)
A2: P_1.1 | B2: 1. | C2: 1.1 | D2: 1.1 | E2: การปรับปรุงโครงสร้างการดำเนินงานด้าน GRC เพื่อการดำเนินงานระดับสายงาน | G2: 8.3 | H2: 16.7 | I2: 25 | J2: 33.3 | K2: 41.7 | L2: 50 | M2: 58.3 | N2: 66.7 | O2: 75 | P2: 83.3 | Q2: 91.7 | R2: 100 | S2: 8.3 | T2: 16.7 | U2: 25 | V2: 33.3 | W2: 41.7 | X2: 50 | Y2: 58.3 | Z2: 66.7 | AA2: 75 | AB2: 83.3 | AE2: ดำเนินการ การปรับปรุงโครงสร้าง เป็นไปตามแผน (ถึง ต.ค.) | AG2: - | AH2: 2.08
A3: P_1.2 | B3: 1. | C3: 1.2 | D3: 1.2 | E3: โครงสร้างหน่วยงานที่ทำหน้าที่รับผิดชอบการกำกับดูแลด้าน IT Risk และ IT Compliance (รวมถึงระบบเทคโนโลยีดิจิทัล และ AI) (2nd line) | G3: 8.3 | H3: 16.7 | I3: 25 | J3: 33.3 | K3: 41.7 | L3: 50 | M3: 58.3 | N3: 66.7 | O3: 75 | P3: 83.3 | Q3: 91.7 | R3: 100 | S3: 8.3 | T3: 16.7 | U3: 25 | V3: 33.3 | W3: 41.7 | X3: 50 | Y3: 58.3 | Z3: 66.7 | AA3: 75 | AB3: 83.3 | AE3: ดำเนินการ โครงสร้างหน่วยงานที่ เป็นไปตามแผน (ถึง ต.ค.) | AG3: - | AH3: 2.08
A4: P_1.3 | B4: 1. | C4: 1.3 | D4: 1.3 | E4: การจัดทำ Risk Taxonomy เพื่อความสอดคล้องในการระบุ และจัดประเภทความเสี่ยง | G4: 8.3 | H4: 16.7 | I4: 25 | J4: 33.3 | K4: 41.7 | L4: 50 | M4: 58.3 | N4: 66.7 | O4: 75 | P4: 83.3 | Q4: 91.7 | R4: 100 | S4: 8.3 | T4: 16.7 | U4: 25 | V4: 33.3 | W4: 41.7 | X4: 50 | Y4: 58.3 | Z4: 66.7 | AA4: 75 | AB4: 83.3 | AE4: ดำเนินการ การจัดทำ Risk Taxono เป็นไปตามแผน (ถึง ต.ค.) | AG4: - | AH4: 2.08
A5: P_1.4 | B5: 1. | C5: 1.4 | D5: 1.4 | E5: การวิเคราะห์ตัวชี้วัดความเสี่ยง (KRI) เพื่อวิเคราะห์แนวโน้ม และคาดการณ์เหตุการณ์ความเสี่ยง | J5: 33.3 | K5: 66.7 | L5: 100 | M5: 100 | N5: 100 | O5: 100 | P5: 100 | Q5: 100 | R5: 100 | V5: 33.3 | W5: 66.7 | X5: 100 | Y5: 100 | Z5: 100 | AA5: 100 | AB5: 100 | AE5: ดำเนินการ การวิเคราะห์ตัวชี้วั เป็นไปตามแผน (ถึง ต.ค.) | AG5: - | AH5: 2.08
A6: P_1.5 | B6: 1. | C6: 1.5 | D6: 1.5 | E6: การสร้างวัฒนธรรม GRC ผ่าน GRC Survey และการสนทนากลุ่ม (Focus Group) | M6: 20 | N6: 40 | O6: 60 | P6: 80 | Q6: 100 | R6: 100 | Y6: 20 | Z6: 40 | AA6: 60 | AB6: 80 | AE6: ดำเนินการ การสร้างวัฒนธรรม GRC เป็นไปตามแผน (ถึง ต.ค.) | AG6: - | AH6: 2.08
A7: P_1.6 | B7: 1. | C7: 1.6 | D7: 1.6 | E7: การพัฒนากระบวนการจัดทำหลักสูตรอบรมโดยอ้างอิงความเสี่ยง (Risk-based training) และติดตามผลการอบรม | P7: 33.3 | Q7: 66.7 | R7: 100 | AB7: 33.3 | AE7: ดำเนินการ การพัฒนากระบวนการจัด เป็นไปตามแผน (ถึง ต.ค.) | AG7: - | AH7: 2.08
A8: P_1.7 | B8: 1. | C8: 1.7 | D8: 1.7 | E8: การเชื่อมโยงการปฏิบัติงานด้าน GRC กับสิ่งจูงใจ (Incentive) หรือผลการปฏิบัติงาน (Performance) | P8: 33.3 | Q8: 66.7 | R8: 100 | AB8: 33.3 | AE8: ดำเนินการ การเชื่อมโยงการปฏิบั เป็นไปตามแผน (ถึง ต.ค.) | AG8: - | AH8: 2.08
A9: P_1.8 | B9: 1. | C9: 1.8 | D9: 1.8 | E9: การปรับปรุงนโยบายการกำกับการปฏิบัติตามกฎ ระเบียบและจัดทำนโยบาย IT Third Party Risk Management | P9: 33.3 | Q9: 66.7 | R9: 100 | AB9: 33.3 | AE9: ดำเนินการ การปรับปรุงนโยบายการ เป็นไปตามแผน (ถึง ต.ค.) | AG9: - | AH9: 2.08
A10: P_1.9 | B10: 1. | C10: 1.9 | D10: 1.9 | E10: การผลักดันให้มีหน่วยงานกลางกำกับและรวบรวมนโยบาย | G10: 8.3 | H10: 16.7 | I10: 25 | J10: 33.3 | K10: 41.7 | L10: 50 | M10: 58.3 | N10: 66.7 | O10: 75 | P10: 83.3 | Q10: 91.7 | R10: 100 | S10: 8.3 | T10: 16.7 | U10: 25 | V10: 33.3 | W10: 41.7 | X10: 50 | Y10: 58.3 | Z10: 66.7 | AA10: 75 | AB10: 83.3 | AE10: ดำเนินการ การผลักดันให้มีหน่วย เป็นไปตามแผน (ถึง ต.ค.) | AG10: - | AH10: 2.08
A11: P_1.10 | B11: 1. | C11: 1.10 | D11: 1.10 | E11: การบูรณาการข้อมูลกระบวนงาน | J11: 16.7 | K11: 33.3 | L11: 50 | M11: 66.7 | N11: 83.3 | O11: 100 | P11: 100 | Q11: 100 | R11: 100 | V11: 16.7 | W11: 33.3 | X11: 50 | Y11: 66.7 | Z11: 83.3 | AA11: 100 | AB11: 100 | AE11: ดำเนินการ การบูรณาการข้อมูลกระ เป็นไปตามแผน (ถึง ต.ค.) | AG11: - | AH11: 2.08
A12: P_1.11 | B12: 1. | C12: 1.11 | D12: 1.11 | E12: การปรับแนวทางการประเมิน CSA | M12: 33.3 | N12: 66.7 | O12: 100 | P12: 100 | Q12: 100 | R12: 100 | Y12: 33.3 | Z12: 66.7 | AA12: 100 | AB12: 100 | AE12: ดำเนินการ การปรับแนวทางการประเ เป็นไปตามแผน (ถึง ต.ค.) | AG12: - | AH12: 2.08
A13: P_1.12 | B13: 1. | C13: 1.12 | D13: 1.12 | E13: การจัดทำแนวทาง/เอกสารในการรวบรวมข้อมูลเหตุการณ์ (Incident information) | G13: 8.3 | H13: 16.7 | I13: 25 | J13: 33.3 | K13: 41.7 | L13: 50 | M13: 58.3 | N13: 66.7 | O13: 75 | P13: 83.3 | Q13: 91.7 | R13: 100 | S13: 8.3 | T13: 16.7 | U13: 25 | V13: 33.3 | W13: 41.7 | X13: 50 | Y13: 58.3 | Z13: 66.7 | AA13: 75 | AB13: 83.3 | AE13: ดำเนินการ การจัดทำแนวทาง/เอกสา เป็นไปตามแผน (ถึง ต.ค.) | AG13: - | AH13: 2.08
A14: P_1.13 | B14: 1. | C14: 1.13 | D14: 1.13 | E14: การพัฒนาเครื่องมือติดตามประสิทธิภาพการควบคุมอย่างต่อเนื่อง (Continuous Monitoring) | G14: 8.3 | H14: 16.7 | I14: 25 | J14: 33.3 | K14: 41.7 | L14: 50 | M14: 58.3 | N14: 66.7 | O14: 75 | P14: 83.3 | Q14: 91.7 | R14: 100 | S14: 8.3 | T14: 16.7 | U14: 25 | V14: 33.3 | W14: 41.7 | X14: 50 | Y14: 58.3 | Z14: 66.7 | AA14: 75 | AB14: 83.3 | AE14: ดำเนินการ การพัฒนาเครื่องมือติ เป็นไปตามแผน (ถึง ต.ค.) | AG14: - | AH14: 2.08
A15: P_1.14 | B15: 1. | C15: 1.14 | D15: 1.14 | E15: การพัฒนาทะเบียนกฎหมาย เนื้อหาข้อบังคับที่องค์กรต้องปฏิบัติตาม (Citation) และเชื่อมโยงกับการควบคุมและนโยบาย | G15: 8.3 | H15: 16.7 | I15: 25 | J15: 33.3 | K15: 41.7 | L15: 50 | M15: 58.3 | N15: 66.7 | O15: 75 | P15: 83.3 | Q15: 91.7 | R15: 100 | S15: 8.3 | T15: 16.7 | U15: 25 | V15: 33.3 | W15: 41.7 | X15: 50 | Y15: 58.3 | Z15: 66.7 | AA15: 75 | AB15: 83.3 | AE15: ดำเนินการ การพัฒนาทะเบียนกฎหมา เป็นไปตามแผน (ถึง ต.ค.) | AG15: - | AH15: 2.08
A16: M_2.1.1 | B16: 2. | C16: 2.1 | D16: 2.1.1 | E16: ทบทวนนโยบาย GRC | F16: งานบริหารความเสี่ยง / พี่หนึ่ง | M16: 10 | N16: 30 | O16: 40 | P16: 50 | Q16: 70 | R16: 100 | Y16: 10 | Z16: 30 | AA16: 40 | AB16: 50 | AE16: ดำเนินการ ทบทวนนโยบาย GRC เป็นไปตามแผน (ถึง ต.ค.) | AG16: พี่หนึ่ง | AH16: 2.08
A17: M_2.1.2 | B17: 2. | C17: 2.1 | D17: 2.1.2 | E17: ทบทวนโครงสร้างและบทบาทหน้าที่ด้านการบริหารความเสี่ยง | F17: งานบริหารความเสี่ยง / พี่หนึ่ง | K17: 12.5 | L17: 25 | M17: 37.5 | N17: 50 | O17: 62.5 | P17: 75 | Q17: 87.5 | R17: 100 | W17: 12.5 | X17: 25 | Y17: 37.5 | Z17: 50 | AA17: 62.5 | AB17: 75 | AE17: ดำเนินการ ทบทวนโครงสร้างและบทบ เป็นไปตามแผน (ถึง ต.ค.) | AG17: พี่หนึ่ง | AH17: 2.08
A18: M_2.1.3 | B18: 2. | C18: 2.1 | D18: 2.1.3 | E18: ทบทวนกรอบการดำเนินงานและคู่มือการบริหารความเสี่ยง | F18: งานบริหารความเสี่ยง / พี่หนึ่ง | L18: 12.5 | M18: 25 | N18: 50 | O18: 62.5 | P18: 75 | Q18: 87.5 | R18: 100 | X18: 12.5 | Y18: 25 | Z18: 50 | AA18: 62.5 | AB18: 75 | AE18: ดำเนินการ ทบทวนกรอบการดำเนินงา เป็นไปตามแผน (ถึง ต.ค.) | AG18: พี่หนึ่ง | AH18: 2.08
A19: M_2.2.1 | B19: 2. | C19: 2.2 | D19: 2.2.1 | E19: ทบทวน Competency / พฤติกรรมพึงประสงค์ด้านการบริหารความเสี่ยง กับผู้บริหาร และพนักงานที่เกี่ยวข้อง | F19: งานบริหารความเสี่ยง / แบม | G19: 16.7 | H19: 33.3 | I19: 50 | J19: 66.7 | K19: 83.3 | L19: 100 | M19: 100 | N19: 100 | O19: 100 | P19: 100 | Q19: 100 | R19: 100 | S19: 16.7 | T19: 33.3 | U19: 50 | V19: 66.7 | W19: 83.3 | X19: 100 | Y19: 100 | Z19: 100 | AA19: 100 | AB19: 100 | AE19: ดำเนินการ ทบทวน Competency / พ เป็นไปตามแผน (ถึง ต.ค.) | AG19: แบม | AH19: 2.08
A20: M_2.2.2 | B20: 2. | C20: 2.2 | D20: 2.2.2 | E20: อบรมและพัฒนาพนักงานตาม Competency ที่กำหนด | F20: งานบริหารความเสี่ยง / แบม | G20: 3.8 | H20: 7.7 | I20: 11.5 | J20: 19.2 | K20: 26.9 | L20: 34.6 | M20: 42.3 | N20: 50 | O20: 61.5 | P20: 76.9 | Q20: 88.5 | R20: 100 | S20: 3.8 | T20: 7.7 | U20: 11.5 | V20: 19.2 | W20: 26.9 | X20: 34.6 | Y20: 42.3 | Z20: 50 | AA20: 61.5 | AB20: 76.9 | AE20: ดำเนินการ อบรมและพัฒนาพนักงานต เป็นไปตามแผน (ถึง ต.ค.) | AG20: แบม | AH20: 2.08
A21: M_2.2.3 | B21: 2. | C21: 2.2 | D21: 2.2.3 | E21: สื่อสารสร้างความตระหนักด้านการบริหารความเสี่ยง | F21: งานบริหารความเสี่ยง / แบม | G21: 11.1 | H21: 33.3 | I21: 44.4 | J21: 55.6 | K21: 61.1 | L21: 66.7 | M21: 72.2 | N21: 77.8 | O21: 83.3 | P21: 88.9 | Q21: 94.4 | R21: 100 | S21: 11.1 | T21: 33.3 | U21: 44.4 | V21: 55.6 | W21: 61.1 | X21: 66.7 | Y21: 72.2 | Z21: 77.8 | AA21: 83.3 | AB21: 88.9 | AE21: ดำเนินการ สื่อสารสร้างความตระห เป็นไปตามแผน (ถึง ต.ค.) | AG21: แบม | AH21: 2.08
A22: M_2.2.4 | B22: 2. | C22: 2.2 | D22: 2.2.4 | E22: สำรวจความตระหนักและทัศนคติเกี่ยวกับการบริหารความเสี่ยง | F22: งานบริหารความเสี่ยง / แบม | M22: 14.3 | N22: 28.6 | O22: 57.1 | P22: 71.4 | Q22: 85.7 | R22: 100 | Y22: 14.3 | Z22: 28.6 | AA22: 57.1 | AB22: 71.4 | AE22: ดำเนินการ สำรวจความตระหนักและท เป็นไปตามแผน (ถึง ต.ค.) | AG22: แบม | AH22: 2.08
A23: M_2.2.5 | B23: 2. | C23: 2.2 | D23: 2.2.5 | E23: ทบทวนการจัดทำการเชื่อมโยง KPI กับผลการดำเนินงานด้านการบริหารความเสี่ยงของแต่ละสายงาน | F23: งานบริหารความเสี่ยง / แบม | G23: 12.5 | H23: 37.5 | I23: 50 | J23: 75 | K23: 100 | L23: 100 | M23: 100 | N23: 100 | O23: 100 | P23: 100 | Q23: 100 | R23: 100 | S23: 12.5 | T23: 37.5 | U23: 50 | V23: 75 | W23: 100 | X23: 100 | Y23: 100 | Z23: 100 | AA23: 100 | AB23: 100 | AE23: ดำเนินการ ทบทวนการจัดทำการเชื่ เป็นไปตามแผน (ถึง ต.ค.) | AG23: แบม | AH23: 2.08
A24: M_2.2.6 | B24: 2. | C24: 2.2 | D24: 2.2.6 | E24: ดำเนินการตามโครงการ MEA GRC Award เพื่อบูรณาการการบริหารความเสี่ยงกับผลตอบแทน/แรงจูงใจ | F24: เจ้นท์ / แบม | G24: 5.9 | H24: 11.8 | I24: 23.5 | J24: 35.3 | K24: 41.2 | L24: 47.1 | M24: 52.9 | N24: 58.8 | O24: 64.7 | P24: 76.5 | Q24: 88.2 | R24: 100 | S24: 5.9 | T24: 11.8 | U24: 23.5 | V24: 35.3 | W24: 41.2 | X24: 47.1 | Y24: 52.9 | Z24: 58.8 | AA24: 64.7 | AB24: 76.5 | AE24: ดำเนินการ ดำเนินการตามโครงการ เป็นไปตามแผน (ถึง ต.ค.) | AG24: แบม | AH24: 2.08
A25: M_2.3.1 | B25: 2. | C25: 2.3 | D25: 2.3.1 | E25: ทบทวนหลักการกำหนด RA/RT และ RA Statement พร้อมสื่อสารให้แก่ผู้มีส่วนได้ส่วนเสีย | F25: งานบริหารความเสี่ยง / เป็ด | G25: 6.7 | H25: 13.3 | I25: 26.7 | J25: 46.7 | K25: 66.7 | L25: 86.7 | M25: 100 | N25: 100 | O25: 100 | P25: 100 | Q25: 100 | R25: 100 | S25: 6.7 | T25: 13.3 | U25: 26.7 | V25: 46.7 | W25: 66.7 | X25: 86.7 | Y25: 100 | Z25: 100 | AA25: 100 | AB25: 100 | AE25: ดำเนินการ ทบทวนหลักการกำหนด RA เป็นไปตามแผน (ถึง ต.ค.) | AF25: ล่าช้ากว่าแผน ติดขั้นตอนอนุมัติ | AG25: เป็ด | AH25: 2.08
A26: M_2.3.2 | B26: 2. | C26: 2.3 | D26: 2.3.2 | E26: ระบุ Emerging Risk เป็นข้อมูลนำเข้าในการวิเคราะห์สภาพแวดล้อม | F26: งานบริหารความเสี่ยง / เป็ด | G26: 6.7 | H26: 20 | I26: 40 | J26: 46.7 | K26: 53.3 | L26: 60 | M26: 66.7 | N26: 73.3 | O26: 80 | P26: 86.7 | Q26: 93.3 | R26: 100 | S26: 6.7 | T26: 20 | U26: 40 | V26: 46.7 | W26: 53.3 | X26: 60 | Y26: 66.7 | Z26: 73.3 | AA26: 80 | AB26: 86.7 | AE26: ดำเนินการ ระบุ Emerging Risk เ เป็นไปตามแผน (ถึง ต.ค.) | AG26: เป็ด | AH26: 2.08
A27: M_2.3.3 | B27: 2. | C27: 2.3 | D27: 2.3.3 | E27: ระบุ Intelligent Risk ที่อาจส่งผลต่อบรรลุเป้าหมายในแต่ละตำแหน่งเชิงยุทธศาสตร์ขององค์กร | F27: งานบริหารความเสี่ยง / เป็ด | J27: 25 | K27: 50 | L27: 75 | M27: 100 | N27: 100 | O27: 100 | P27: 100 | Q27: 100 | R27: 100 | V27: 25 | W27: 50 | X27: 75 | Y27: 100 | Z27: 100 | AA27: 100 | AB27: 100 | AE27: ดำเนินการ ระบุ Intelligent Ris เป็นไปตามแผน (ถึง ต.ค.) | AG27: เป็ด | AH27: 2.08
A28: M_2.3.4 | B28: 2. | C28: 2.3 | D28: 2.3.4 | E28: ระบุและวิเคราะห์ความเสี่ยงที่อาจส่งผลต่อการบรรลุวัตถุประสงค์เชิงยุทธศาสตร์ (SO) | F28: งานบริหารความเสี่ยง / เป็ด | J28: 25 | K28: 50 | L28: 75 | M28: 100 | N28: 100 | O28: 100 | P28: 100 | Q28: 100 | R28: 100 | V28: 25 | W28: 50 | X28: 75 | Y28: 100 | Z28: 100 | AA28: 100 | AB28: 100 | AE28: ดำเนินการ ระบุและวิเคราะห์ความ เป็นไปตามแผน (ถึง ต.ค.) | AG28: เป็ด | AH28: 2.08
A29: M_2.3.5 | B29: 2. | C29: 2.3 | D29: 2.3.5 | E29: ทบทวนแบบฟอร์มและเกณฑ์การประเมินความเสี่ยงและ ประสิทธิผลของการควบคุมของแผน AP และแผนแม่บทที่เกี่ยวข้อง | F29: งานบริหารความเสี่ยง / เป็ด | K29: 33.3 | L29: 66.7 | M29: 100 | N29: 100 | O29: 100 | P29: 100 | Q29: 100 | R29: 100 | W29: 33.3 | X29: 66.7 | Y29: 100 | Z29: 100 | AA29: 100 | AB29: 100 | AE29: ดำเนินการ ทบทวนแบบฟอร์มและเกณฑ เป็นไปตามแผน (ถึง ต.ค.) | AG29: เป็ด | AH29: 2.08
A30: M_2.3.6 | B30: 2. | C30: 2.3 | D30: 2.3.6 | E30: สื่อสารแบบฟอร์มการประเมินความเสี่ยง และหลักเกณฑ์การประเมินความเพียงพอของการควบคุมภายใน | F30: งานบริหารความเสี่ยง / เป็ด | L30: 50 | M30: 100 | N30: 100 | O30: 100 | P30: 100 | Q30: 100 | R30: 100 | X30: 50 | Y30: 100 | Z30: 100 | AA30: 100 | AB30: 100 | AE30: ดำเนินการ สื่อสารแบบฟอร์มการปร เป็นไปตามแผน (ถึง ต.ค.) | AG30: เป็ด | AH30: 2.08
A31: M_2.3.7 | B31: 2. | C31: 2.3 | D31: 2.3.7 | E31: ติดตามการวิเคราะห์ ระบุ และประเมินความเสี่ยงของแผนปฏิบัติการ และแผนแม่บทที่เกี่ยวข้อง พร้อมกำหนดมาตรการจัดการความเสี่ยง | F31: งานบริหารความเสี่ยง / เป็ด | L31: 40 | M31: 60 | N31: 80 | O31: 100 | P31: 100 | Q31: 100 | R31: 100 | X31: 40 | Y31: 60 | Z31: 80 | AA31: 100 | AB31: 100 | AE31: ดำเนินการ ติดตามการวิเคราะห์ ร เป็นไปตามแผน (ถึง ต.ค.) | AF31: ล่าช้ากว่าแผน ติดขั้นตอนอนุมัติ | AG31: เป็ด | AH31: 2.08
A32: M_2.4.1 | B32: 2. | C32: 2.4 | D32: 2.4.1 | E32: รวบรวม/วิเคราะห์ข้อมูลความเสี่ยง การควบคุม และนำเข้าใน Risk Inventory พร้อมทบทวนเกณฑ์ประเมินการควบคุม | F32: งานบริหารความเสี่ยง | G32: 5.3 | H32: 10.5 | I32: 15.8 | J32: 21.1 | K32: 31.6 | L32: 47.4 | M32: 63.2 | N32: 68.4 | O32: 73.7 | P32: 78.9 | Q32: 89.5 | R32: 100 | S32: 5.3 | T32: 10.5 | U32: 15.8 | V32: 21.1 | W32: 31.6 | X32: 47.4 | Y32: 63.2 | Z32: 68.4 | AA32: 73.7 | AB32: 78.9 | AE32: ดำเนินการ รวบรวม/วิเคราะห์ข้อม เป็นไปตามแผน (ถึง ต.ค.) | AG32: งานบริหารความเสี่ยง | AH32: 2.08
A33: M_2.4.2 | B33: 2. | C33: 2.4 | D33: 2.4.2 | E33: คัดเลือกปัจจัยเสี่ยงระดับองค์กร พร้อมวิเคราะห์ Leading / Lagging Indicator ของแต่ละความเสี่ยง | F33: งานบริหารความเสี่ยง | L33: 33.3 | M33: 66.7 | N33: 100 | O33: 100 | P33: 100 | Q33: 100 | R33: 100 | X33: 33.3 | Y33: 66.7 | Z33: 100 | AA33: 100 | AB33: 100 | AE33: ดำเนินการ คัดเลือกปัจจัยเสี่ยง เป็นไปตามแผน (ถึง ต.ค.) | AG33: งานบริหารความเสี่ยง | AH33: 2.08
A34: M_2.4.3 | B34: 2. | C34: 2.4 | D34: 2.4.3 | E34: จัดให้มีการประเมินความเสี่ยง และสื่อสารความเสี่ยงต่อผู้รับผิดชอบ | F34: งานบริหารความเสี่ยง | M34: 20 | N34: 40 | O34: 80 | P34: 100 | Q34: 100 | R34: 100 | Y34: 20 | Z34: 40 | AA34: 80 | AB34: 100 | AE34: ดำเนินการ จัดให้มีการประเมินคว เป็นไปตามแผน (ถึง ต.ค.) | AG34: งานบริหารความเสี่ยง | AH34: 2.08
A35: M_2.4.4 | B35: 2. | C35: 2.4 | D35: 2.4.4 | E35: พิจารณาและคัดเลือกวิธีการจัดการความเสี่ยง พร้อมทั้ง วิเคราะห์และจัดทำ Risk Correlation Map/Portfolio View of Risk | F35: งานบริหารความเสี่ยง | N35: 14.3 | O35: 42.9 | P35: 71.4 | Q35: 100 | R35: 100 | Z35: 14.3 | AA35: 42.9 | AB35: 71.4 | AE35: ดำเนินการ พิจารณาและคัดเลือกวิ เป็นไปตามแผน (ถึง ต.ค.) | AG35: งานบริหารความเสี่ยง | AH35: 2.08
A36: M_2.4.5 | B36: 2. | C36: 2.4 | D36: 2.4.5 | E36: จัดทำแผนบริหารความเสี่ยง และทบทวนแผนบริหารความเสี่ยงของปีถัดไป | F36: งานบริหารความเสี่ยง | N36: 25 | O36: 50 | P36: 75 | Q36: 100 | R36: 100 | Z36: 25 | AA36: 50 | AB36: 75 | AE36: ดำเนินการ จัดทำแผนบริหารความเส เป็นไปตามแผน (ถึง ต.ค.) | AG36: งานบริหารความเสี่ยง | AH36: 2.08
A37: M_2.4.6 | B37: 2. | C37: 2.4 | D37: 2.4.6 | E37: ติดตามและรายงานผลการบริหารความเสี่ยงและการควบคุมของความเสี่ยงปีปัจจุบัน | F37: งานบริหารความเสี่ยง | G37: 7.1 | H37: 14.3 | I37: 21.4 | J37: 32.1 | K37: 39.3 | L37: 46.4 | M37: 57.1 | N37: 64.3 | O37: 71.4 | P37: 82.1 | Q37: 89.3 | R37: 100 | S37: 7.1 | T37: 14.3 | U37: 21.4 | V37: 32.1 | W37: 39.3 | X37: 46.4 | Y37: 57.1 | Z37: 64.3 | AA37: 71.4 | AB37: 82.1 | AE37: ดำเนินการ ติดตามและรายงานผลการ เป็นไปตามแผน (ถึง ต.ค.) | AG37: งานบริหารความเสี่ยง | AH37: 2.08
A38: M_2.4.7 | B38: 2. | C38: 2.4 | D38: 2.4.7 | E38: พัฒนาระบบเทคโนโลยีดิจิทัลเพื่อสนับสนุนกระบวนการบริหารความเสี่ยง และระบบเตือนภัยล่วงหน้า | F38: งานบริหารความเสี่ยง | G38: 8.3 | H38: 16.7 | I38: 25 | J38: 33.3 | K38: 41.7 | L38: 50 | M38: 58.3 | N38: 66.7 | O38: 75 | P38: 83.3 | Q38: 91.7 | R38: 100 | S38: 8.3 | T38: 16.7 | U38: 25 | V38: 33.3 | W38: 41.7 | X38: 50 | Y38: 58.3 | Z38: 66.7 | AA38: 75 | AB38: 83.3 | AE38: ดำเนินการ พัฒนาระบบเทคโนโลยีดิ เป็นไปตามแผน (ถึง ต.ค.) | AG38: งานบริหารความเสี่ยง | AH38: 2.08
A39: M_2.4.8 | B39: 2. | C39: 2.4 | D39: 2.4.8 | E39: ทบทวน ประเมินประสิทธิผล และปรับปรุงกระบวนการบริหารความเสี่ยง | F39: งานบริหารความเสี่ยง | P39: 42.9 | Q39: 85.7 | R39: 142.9 | AB39: 42.9 | AE39: ดำเนินการ ทบทวน ประเมินประสิทธ เป็นไปตามแผน (ถึง ต.ค.) | AG39: งานบริหารความเสี่ยง | AH39: 2.08
A40: M_2.5.1 | B40: 2. | C40: 2.5 | D40: 2.5.1 | E40: วิเคราะห์ผลกระทบทางธุรกิจ ประเมินความเสี่ยง ทบทวนกลยุทธ์ และ BCP | F40: งานบริหารความเสี่ยง | G40: 6.7 | H40: 13.3 | I40: 26.7 | J40: 33.3 | K40: 46.7 | L40: 53.3 | M40: 66.7 | N40: 73.3 | O40: 80 | P40: 86.7 | Q40: 93.3 | R40: 100 | S40: 6.7 | T40: 13.3 | U40: 26.7 | V40: 33.3 | W40: 46.7 | X40: 53.3 | Y40: 66.7 | Z40: 73.3 | AA40: 80 | AB40: 86.7 | AE40: ดำเนินการ วิเคราะห์ผลกระทบทางธ เป็นไปตามแผน (ถึง ต.ค.) | AG40: งานบริหารความเสี่ยง | AH40: 2.08
...

Sheet วิธีใช้
A1: วิธีกรอกและนำเข้า Dashboard
A3: 1) | B3: ชีต "บันทึกผล" — แต่ละแถวคือกิจกรรม 1 ข้อ (48 แถว) (คอลัมน์ 1-6 และ "ถ่วงน้ำหนัก(%)" เติมให้แล้ว ห้ามแก้รหัส/น้ำหนัก)
A4: 2) | B4: กลุ่ม "เป้า ม.ค.–ธ.ค." (พื้นเหลือง) = ค่าเป้าหมาย % สะสม — พรีฟิลตามแผนให้แล้ว แก้ได้ตามต้องการ
A5: 3) | B5: กลุ่ม "ผล ม.ค.–ธ.ค." (พื้นฟ้า) = % ผลจริงสะสม กรอกเฉพาะเดือนที่อัปเดต
B6: เดือนที่เว้นว่าง ระบบถือว่าคงค่าล่าสุด (ทั้งเป้าหมายและผลจริง)
A7: 4) | B7: รายละเอียด/ปัญหา/ผู้รายงาน = ของเดือนล่าสุด
A9: แปลงเข้า GitHub:
A10: 5) | B10: python3 ระบบสร้าง_Dashboard/convert_to_csv.py → สร้าง data/rm_actual.csv + อัปเดต index.html
A11: 6) | B11: git add -A && git commit -m "update" && git push
A13: หมายเหตุ | B13: เป้าหมายทุกระดับใน Dashboard (48 กิจกรรม, 3 กล่องแผนหลัก, กราฟ S-Curve/แท่ง) อ้างอิงจากคอลัมน์ "เป้า" ในไฟล์นี้ทั้งหมด
B14: ตัวเลขเป้าหมายระดับแผนหลักคือค่าเฉลี่ยถ่วงน้ำหนัก (ตามคอลัมน์ "ถ่วงน้ำหนัก(%)") ของกิจกรรมในแผนนั้น — ดูสูตรจริงได้ที่ชีต "สรุปเป้าหมายตามแผน"
B15: ชีต "สรุปเป้าหมายตามแผน" คำนวณสดด้วยสูตร SUMPRODUCT จากคอลัมน์เป้า+น้ำหนัก แก้เป้าหมายกิจกรรมใดก็ตาม ตัวเลขแผนหลักในชีตนี้จะขยับให้อัตโนมัติ (ตรงกับที่ Dashboard จะแสดง)
B16: สถานะงานคำนวณจากผลจริง: 100=เสร็จสิ้น · 1-99=อยู่ระหว่างดำเนินการ · 0/ว่าง=ยังไม่ดำเนินการ

Sheet สรุปรายเดือน_กิจกรรม
A1: รหัสกิจกรรม | B1: รหัส | C1: ชื่อกิจกรรม/มาตรการ | D1: แผนหลัก | E1: สรุป ม.ค. | F1: สรุป ก.พ. | G1: สรุป มี.ค. | H1: สรุป เม.ย. | I1: สรุป พ.ค. | J1: สรุป มิ.ย. | K1: สรุป ก.ค. | L1: สรุป ส.ค. | M1: สรุป ก.ย. | N1: สรุป ต.ค. | O1: สรุป พ.ย. | P1: สรุป ธ.ค.
A2: P_1.1 | B2: 1.1 | C2: การปรับปรุงโครงสร้างการดำเนินงานด้าน GRC เพื่อการดำเนินงานระดับสายงาน | D2: 1. | E2: ดำเนินการ การปรับปรุงโครงสร้างการดำเนินง ตามแผนในเดือนม.ค. (สรุปย่อ — แก้เป็นเนื้อหาจริงได้) | F2: ดำเนินการ การปรับปรุงโครงสร้างการดำเนินง ตามแผนในเดือนก.พ. (สรุปย่อ — แก้เป็นเนื้อหาจริงได้) | G2: ดำเนินการ การปรับปรุงโครงสร้างการดำเนินง ตามแผนในเดือนมี.ค. (สรุปย่อ — แก้เป็นเนื้อหาจริงได้) | H2: ดำเนินการ การปรับปรุงโครงสร้างการดำเนินง ตามแผนในเดือนเม.ย. (สรุปย่อ — แก้เป็นเนื้อหาจริงได้) | I2: ดำเนินการ การปรับปรุงโครงสร้างการดำเนินง ตามแผนในเดือนพ.ค. (สรุปย่อ — แก้เป็นเนื้อหาจริงได้) | J2: ดำเนินการ การปรับปรุงโครงสร้างการดำเนินง ตามแผนในเดือนมิ.ย. (สรุปย่อ — แก้เป็นเนื้อหาจริงได้)
A3: P_1.2 | B3: 1.2 | C3: โครงสร้างหน่วยงานที่ทำหน้าที่รับผิดชอบการกำกับดูแลด้าน IT Risk และ IT Compliance (รวมถึงระบบเทคโนโลยีดิจิทัล และ AI) (2nd line) | D3: 1. | E3: ดำเนินการ โครงสร้างหน่วยงานที่ทำหน้าที่ร ตามแผนในเดือนม.ค. (สรุปย่อ — แก้เป็นเนื้อหาจริงได้) | F3: ดำเนินการ โครงสร้างหน่วยงานที่ทำหน้าที่ร ตามแผนในเดือนก.พ. (สรุปย่อ — แก้เป็นเนื้อหาจริงได้) | G3: ดำเนินการ โครงสร้างหน่วยงานที่ทำหน้าที่ร ตามแผนในเดือนมี.ค. (สรุปย่อ — แก้เป็นเนื้อหาจริงได้) | H3: ดำเนินการ โครงสร้างหน่วยงานที่ทำหน้าที่ร ตามแผนในเดือนเม.ย. (สรุปย่อ — แก้เป็นเนื้อหาจริงได้) | I3: ดำเนินการ โครงสร้างหน่วยงานที่ทำหน้าที่ร ตามแผนในเดือนพ.ค. (สรุปย่อ — แก้เป็นเนื้อหาจริงได้) | J3: ดำเนินการ โครงสร้างหน่วยงานที่ทำหน้าที่ร ตามแผนในเดือนมิ.ย. (สรุปย่อ — แก้เป็นเนื้อหาจริงได้)
A4: P_1.3 | B4: 1.3 | C4: การจัดทำ Risk Taxonomy เพื่อความสอดคล้องในการระบุ และจัดประเภทความเสี่ยง | D4: 1. | E4: ดำเนินการ การจัดทำ Risk Taxonomy เพื่อคว ตามแผนในเดือนม.ค. (สรุปย่อ — แก้เป็นเนื้อหาจริงได้) | F4: ดำเนินการ การจัดทำ Risk Taxonomy เพื่อคว ตามแผนในเดือนก.พ. (สรุปย่อ — แก้เป็นเนื้อหาจริงได้) | G4: ดำเนินการ การจัดทำ Risk Taxonomy เพื่อคว ตามแผนในเดือนมี.ค. (สรุปย่อ — แก้เป็นเนื้อหาจริงได้) | H4: ดำเนินการ การจัดทำ Risk Taxonomy เพื่อคว ตามแผนในเดือนเม.ย. (สรุปย่อ — แก้เป็นเนื้อหาจริงได้) | I4: ดำเนินการ การจัดทำ Risk Taxonomy เพื่อคว ตามแผนในเดือนพ.ค. (สรุปย่อ — แก้เป็นเนื้อหาจริงได้) | J4: ดำเนินการ การจัดทำ Risk Taxonomy เพื่อคว ตามแผนในเดือนมิ.ย. (สรุปย่อ — แก้เป็นเนื้อหาจริงได้)
A5: P_1.4 | B5: 1.4 | C5: การวิเคราะห์ตัวชี้วัดความเสี่ยง (KRI) เพื่อวิเคราะห์แนวโน้ม และคาดการณ์เหตุการณ์ความเสี่ยง | D5: 1. | H5: ดำเนินการ การวิเคราะห์ตัวชี้วัดความเสี่ย ตามแผนในเดือนเม.ย. (สรุปย่อ — แก้เป็นเนื้อหาจริงได้) | I5: ดำเนินการ การวิเคราะห์ตัวชี้วัดความเสี่ย ตามแผนในเดือนพ.ค. (สรุปย่อ — แก้เป็นเนื้อหาจริงได้) | J5: ดำเนินการ การวิเคราะห์ตัวชี้วัดความเสี่ย ตามแผนในเดือนมิ.ย. (สรุปย่อ — แก้เป็นเนื้อหาจริงได้)
A6: P_1.5 | B6: 1.5 | C6: การสร้างวัฒนธรรม GRC ผ่าน GRC Survey และการสนทนากลุ่ม (Focus Group) | D6: 1.
A7: P_1.6 | B7: 1.6 | C7: การพัฒนากระบวนการจัดทำหลักสูตรอบรมโดยอ้างอิงความเสี่ยง (Risk-based training) และติดตามผลการอบรม | D7: 1.
A8: P_1.7 | B8: 1.7 | C8: การเชื่อมโยงการปฏิบัติงานด้าน GRC กับสิ่งจูงใจ (Incentive) หรือผลการปฏิบัติงาน (Performance) | D8: 1.
A9: P_1.8 | B9: 1.8 | C9: การปรับปรุงนโยบายการกำกับการปฏิบัติตามกฎ ระเบียบและจัดทำนโยบาย IT Third Party Risk Management | D9: 1.
A10: P_1.9 | B10: 1.9 | C10: การผลักดันให้มีหน่วยงานกลางกำกับและรวบรวมนโยบาย | D10: 1. | E10: ดำเนินการ การผลักดันให้มีหน่วยงานกลางกำก ตามแผนในเดือนม.ค. (สรุปย่อ — แก้เป็นเนื้อหาจริงได้) | F10: ดำเนินการ การผลักดันให้มีหน่วยงานกลางกำก ตามแผนในเดือนก.พ. (สรุปย่อ — แก้เป็นเนื้อหาจริงได้) | G10: ดำเนินการ การผลักดันให้มีหน่วยงานกลางกำก ตามแผนในเดือนมี.ค. (สรุปย่อ — แก้เป็นเนื้อหาจริงได้) | H10: ดำเนินการ การผลักดันให้มีหน่วยงานกลางกำก ตามแผนในเดือนเม.ย. (สรุปย่อ — แก้เป็นเนื้อหาจริงได้) | I10: ดำเนินการ การผลักดันให้มีหน่วยงานกลางกำก ตามแผนในเดือนพ.ค. (สรุปย่อ — แก้เป็นเนื้อหาจริงได้) | J10: ดำเนินการ การผลักดันให้มีหน่วยงานกลางกำก ตามแผนในเดือนมิ.ย. (สรุปย่อ — แก้เป็นเนื้อหาจริงได้)
A11: P_1.10 | B11: 1.10 | C11: การบูรณาการข้อมูลกระบวนงาน | D11: 1. | H11: ดำเนินการ การบูรณาการข้อมูลกระบวนงาน ตามแผนในเดือนเม.ย. (สรุปย่อ — แก้เป็นเนื้อหาจริงได้) | I11: ดำเนินการ การบูรณาการข้อมูลกระบวนงาน ตามแผนในเดือนพ.ค. (สรุปย่อ — แก้เป็นเนื้อหาจริงได้) | J11: ดำเนินการ การบูรณาการข้อมูลกระบวนงาน ตามแผนในเดือนมิ.ย. (สรุปย่อ — แก้เป็นเนื้อหาจริงได้)
A12: P_1.11 | B12: 1.11 | C12: การปรับแนวทางการประเมิน CSA | D12: 1.
A13: P_1.12 | B13: 1.12 | C13: การจัดทำแนวทาง/เอกสารในการรวบรวมข้อมูลเหตุการณ์ (Incident information) | D13: 1. | E13: ดำเนินการ การจัดทำแนวทาง/เอกสารในการรวบร ตามแผนในเดือนม.ค. (สรุปย่อ — แก้เป็นเนื้อหาจริงได้) | F13: ดำเนินการ การจัดทำแนวทาง/เอกสารในการรวบร ตามแผนในเดือนก.พ. (สรุปย่อ — แก้เป็นเนื้อหาจริงได้) | G13: ดำเนินการ การจัดทำแนวทาง/เอกสารในการรวบร ตามแผนในเดือนมี.ค. (สรุปย่อ — แก้เป็นเนื้อหาจริงได้) | H13: ดำเนินการ การจัดทำแนวทาง/เอกสารในการรวบร ตามแผนในเดือนเม.ย. (สรุปย่อ — แก้เป็นเนื้อหาจริงได้) | I13: ดำเนินการ การจัดทำแนวทาง/เอกสารในการรวบร ตามแผนในเดือนพ.ค. (สรุปย่อ — แก้เป็นเนื้อหาจริงได้) | J13: ดำเนินการ การจัดทำแนวทาง/เอกสารในการรวบร ตามแผนในเดือนมิ.ย. (สรุปย่อ — แก้เป็นเนื้อหาจริงได้)
A14: P_1.13 | B14: 1.13 | C14: การพัฒนาเครื่องมือติดตามประสิทธิภาพการควบคุมอย่างต่อเนื่อง (Continuous Monitoring) | D14: 1. | E14: ดำเนินการ การพัฒนาเครื่องมือติดตามประสิท ตามแผนในเดือนม.ค. (สรุปย่อ — แก้เป็นเนื้อหาจริงได้) | F14: ดำเนินการ การพัฒนาเครื่องมือติดตามประสิท ตามแผนในเดือนก.พ. (สรุปย่อ — แก้เป็นเนื้อหาจริงได้) | G14: ดำเนินการ การพัฒนาเครื่องมือติดตามประสิท ตามแผนในเดือนมี.ค. (สรุปย่อ — แก้เป็นเนื้อหาจริงได้) | H14: ดำเนินการ การพัฒนาเครื่องมือติดตามประสิท ตามแผนในเดือนเม.ย. (สรุปย่อ — แก้เป็นเนื้อหาจริงได้) | I14: ดำเนินการ การพัฒนาเครื่องมือติดตามประสิท ตามแผนในเดือนพ.ค. (สรุปย่อ — แก้เป็นเนื้อหาจริงได้) | J14: ดำเนินการ การพัฒนาเครื่องมือติดตามประสิท ตามแผนในเดือนมิ.ย. (สรุปย่อ — แก้เป็นเนื้อหาจริงได้)
A15: P_1.14 | B15: 1.14 | C15: การพัฒนาทะเบียนกฎหมาย เนื้อหาข้อบังคับที่องค์กรต้องปฏิบัติตาม (Citation) และเชื่อมโยงกับการควบคุมและนโยบาย | D15: 1. | E15: ดำเนินการ การพัฒนาทะเบียนกฎหมาย เนื้อหาข ตามแผนในเดือนม.ค. (สรุปย่อ — แก้เป็นเนื้อหาจริงได้) | F15: ดำเนินการ การพัฒนาทะเบียนกฎหมาย เนื้อหาข ตามแผนในเดือนก.พ. (สรุปย่อ — แก้เป็นเนื้อหาจริงได้) | G15: ดำเนินการ การพัฒนาทะเบียนกฎหมาย เนื้อหาข ตามแผนในเดือนมี.ค. (สรุปย่อ — แก้เป็นเนื้อหาจริงได้) | H15: ดำเนินการ การพัฒนาทะเบียนกฎหมาย เนื้อหาข ตามแผนในเดือนเม.ย. (สรุปย่อ — แก้เป็นเนื้อหาจริงได้) | I15: ดำเนินการ การพัฒนาทะเบียนกฎหมาย เนื้อหาข ตามแผนในเดือนพ.ค. (สรุปย่อ — แก้เป็นเนื้อหาจริงได้) | J15: ดำเนินการ การพัฒนาทะเบียนกฎหมาย เนื้อหาข ตามแผนในเดือนมิ.ย. (สรุปย่อ — แก้เป็นเนื้อหาจริงได้)
A16: M_2.1.1 | B16: 2.1.1 | C16: ทบทวนนโยบาย GRC | D16: 2.
A17: M_2.1.2 | B17: 2.1.2 | C17: ทบทวนโครงสร้างและบทบาทหน้าที่ด้านการบริหารความเสี่ยง | D17: 2. | I17: ดำเนินการ ทบทวนโครงสร้างและบทบาทหน้าที่ด ตามแผนในเดือนพ.ค. (สรุปย่อ — แก้เป็นเนื้อหาจริงได้) | J17: ดำเนินการ ทบทวนโครงสร้างและบทบาทหน้าที่ด ตามแผนในเดือนมิ.ย. (สรุปย่อ — แก้เป็นเนื้อหาจริงได้)
A18: M_2.1.3 | B18: 2.1.3 | C18: ทบทวนกรอบการดำเนินงานและคู่มือการบริหารความเสี่ยง | D18: 2. | J18: ดำเนินการ ทบทวนกรอบการดำเนินงานและคู่มือ ตามแผนในเดือนมิ.ย. (สรุปย่อ — แก้เป็นเนื้อหาจริงได้)
A19: M_2.2.1 | B19: 2.2.1 | C19: ทบทวน Competency / พฤติกรรมพึงประสงค์ด้านการบริหารความเสี่ยง กับผู้บริหาร และพนักงานที่เกี่ยวข้อง | D19: 2. | E19: ดำเนินการ ทบทวน Competency / พฤติกรรมพึง ตามแผนในเดือนม.ค. (สรุปย่อ — แก้เป็นเนื้อหาจริงได้) | F19: ดำเนินการ ทบทวน Competency / พฤติกรรมพึง ตามแผนในเดือนก.พ. (สรุปย่อ — แก้เป็นเนื้อหาจริงได้) | G19: ดำเนินการ ทบทวน Competency / พฤติกรรมพึง ตามแผนในเดือนมี.ค. (สรุปย่อ — แก้เป็นเนื้อหาจริงได้) | H19: ดำเนินการ ทบทวน Competency / พฤติกรรมพึง ตามแผนในเดือนเม.ย. (สรุปย่อ — แก้เป็นเนื้อหาจริงได้) | I19: ดำเนินการ ทบทวน Competency / พฤติกรรมพึง ตามแผนในเดือนพ.ค. (สรุปย่อ — แก้เป็นเนื้อหาจริงได้) | J19: ดำเนินการ ทบทวน Competency / พฤติกรรมพึง ตามแผนในเดือนมิ.ย. (สรุปย่อ — แก้เป็นเนื้อหาจริงได้)
A20: M_2.2.2 | B20: 2.2.2 | C20: อบรมและพัฒนาพนักงานตาม Competency ที่กำหนด | D20: 2. | E20: ดำเนินการ อบรมและพัฒนาพนักงานตาม Compete ตามแผนในเดือนม.ค. (สรุปย่อ — แก้เป็นเนื้อหาจริงได้) | F20: ดำเนินการ อบรมและพัฒนาพนักงานตาม Compete ตามแผนในเดือนก.พ. (สรุปย่อ — แก้เป็นเนื้อหาจริงได้) | G20: ดำเนินการ อบรมและพัฒนาพนักงานตาม Compete ตามแผนในเดือนมี.ค. (สรุปย่อ — แก้เป็นเนื้อหาจริงได้) | H20: ดำเนินการ อบรมและพัฒนาพนักงานตาม Compete ตามแผนในเดือนเม.ย. (สรุปย่อ — แก้เป็นเนื้อหาจริงได้) | I20: ดำเนินการ อบรมและพัฒนาพนักงานตาม Compete ตามแผนในเดือนพ.ค. (สรุปย่อ — แก้เป็นเนื้อหาจริงได้) | J20: ดำเนินการ อบรมและพัฒนาพนักงานตาม Compete ตามแผนในเดือนมิ.ย. (สรุปย่อ — แก้เป็นเนื้อหาจริงได้)
A21: M_2.2.3 | B21: 2.2.3 | C21: สื่อสารสร้างความตระหนักด้านการบริหารความเสี่ยง | D21: 2. | E21: ดำเนินการ สื่อสารสร้างความตระหนักด้านการ ตามแผนในเดือนม.ค. (สรุปย่อ — แก้เป็นเนื้อหาจริงได้) | F21: ดำเนินการ สื่อสารสร้างความตระหนักด้านการ ตามแผนในเดือนก.พ. (สรุปย่อ — แก้เป็นเนื้อหาจริงได้) | G21: ดำเนินการ สื่อสารสร้างความตระหนักด้านการ ตามแผนในเดือนมี.ค. (สรุปย่อ — แก้เป็นเนื้อหาจริงได้) | H21: ดำเนินการ สื่อสารสร้างความตระหนักด้านการ ตามแผนในเดือนเม.ย. (สรุปย่อ — แก้เป็นเนื้อหาจริงได้) | I21: ดำเนินการ สื่อสารสร้างความตระหนักด้านการ ตามแผนในเดือนพ.ค. (สรุปย่อ — แก้เป็นเนื้อหาจริงได้) | J21: ดำเนินการ สื่อสารสร้างความตระหนักด้านการ ตามแผนในเดือนมิ.ย. (สรุปย่อ — แก้เป็นเนื้อหาจริงได้)
A22: M_2.2.4 | B22: 2.2.4 | C22: สำรวจความตระหนักและทัศนคติเกี่ยวกับการบริหารความเสี่ยง | D22: 2.
A23: M_2.2.5 | B23: 2.2.5 | C23: ทบทวนการจัดทำการเชื่อมโยง KPI กับผลการดำเนินงานด้านการบริหารความเสี่ยงของแต่ละสายงาน | D23: 2. | E23: ดำเนินการ ทบทวนการจัดทำการเชื่อมโยง KPI ตามแผนในเดือนม.ค. (สรุปย่อ — แก้เป็นเนื้อหาจริงได้) | F23: ดำเนินการ ทบทวนการจัดทำการเชื่อมโยง KPI ตามแผนในเดือนก.พ. (สรุปย่อ — แก้เป็นเนื้อหาจริงได้) | G23: ดำเนินการ ทบทวนการจัดทำการเชื่อมโยง KPI ตามแผนในเดือนมี.ค. (สรุปย่อ — แก้เป็นเนื้อหาจริงได้) | H23: ดำเนินการ ทบทวนการจัดทำการเชื่อมโยง KPI ตามแผนในเดือนเม.ย. (สรุปย่อ — แก้เป็นเนื้อหาจริงได้) | I23: ดำเนินการ ทบทวนการจัดทำการเชื่อมโยง KPI ตามแผนในเดือนพ.ค. (สรุปย่อ — แก้เป็นเนื้อหาจริงได้) | J23: ดำเนินการ ทบทวนการจัดทำการเชื่อมโยง KPI ตามแผนในเดือนมิ.ย. (สรุปย่อ — แก้เป็นเนื้อหาจริงได้)
A24: M_2.2.6 | B24: 2.2.6 | C24: ดำเนินการตามโครงการ MEA GRC Award เพื่อบูรณาการการบริหารความเสี่ยงกับผลตอบแทน/แรงจูงใจ | D24: 2. | E24: ดำเนินการ ดำเนินการตามโครงการ MEA GRC Aw ตามแผนในเดือนม.ค. (สรุปย่อ — แก้เป็นเนื้อหาจริงได้) | F24: ดำเนินการ ดำเนินการตามโครงการ MEA GRC Aw ตามแผนในเดือนก.พ. (สรุปย่อ — แก้เป็นเนื้อหาจริงได้) | G24: ดำเนินการ ดำเนินการตามโครงการ MEA GRC Aw ตามแผนในเดือนมี.ค. (สรุปย่อ — แก้เป็นเนื้อหาจริงได้) | H24: ดำเนินการ ดำเนินการตามโครงการ MEA GRC Aw ตามแผนในเดือนเม.ย. (สรุปย่อ — แก้เป็นเนื้อหาจริงได้) | I24: ดำเนินการ ดำเนินการตามโครงการ MEA GRC Aw ตามแผนในเดือนพ.ค. (สรุปย่อ — แก้เป็นเนื้อหาจริงได้) | J24: ดำเนินการ ดำเนินการตามโครงการ MEA GRC Aw ตามแผนในเดือนมิ.ย. (สรุปย่อ — แก้เป็นเนื้อหาจริงได้)
A25: M_2.3.1 | B25: 2.3.1 | C25: ทบทวนหลักการกำหนด RA/RT และ RA Statement พร้อมสื่อสารให้แก่ผู้มีส่วนได้ส่วนเสีย | D25: 2. | E25: ดำเนินการ ทบทวนหลักการกำหนด RA/RT และ RA ตามแผนในเดือนม.ค. (สรุปย่อ — แก้เป็นเนื้อหาจริงได้) | F25: ดำเนินการ ทบทวนหลักการกำหนด RA/RT และ RA ตามแผนในเดือนก.พ. (สรุปย่อ — แก้เป็นเนื้อหาจริงได้) | G25: ดำเนินการ ทบทวนหลักการกำหนด RA/RT และ RA ตามแผนในเดือนมี.ค. (สรุปย่อ — แก้เป็นเนื้อหาจริงได้) | H25: ดำเนินการ ทบทวนหลักการกำหนด RA/RT และ RA ตามแผนในเดือนเม.ย. (สรุปย่อ — แก้เป็นเนื้อหาจริงได้) | I25: ดำเนินการ ทบทวนหลักการกำหนด RA/RT และ RA ตามแผนในเดือนพ.ค. (สรุปย่อ — แก้เป็นเนื้อหาจริงได้) | J25: ดำเนินการ ทบทวนหลักการกำหนด RA/RT และ RA ตามแผนในเดือนมิ.ย. (สรุปย่อ — แก้เป็นเนื้อหาจริงได้)
A26: M_2.3.2 | B26: 2.3.2 | C26: ระบุ Emerging Risk เป็นข้อมูลนำเข้าในการวิเคราะห์สภาพแวดล้อม | D26: 2. | E26: ดำเนินการ ระบุ Emerging Risk เป็นข้อมูลน ตามแผนในเดือนม.ค. (สรุปย่อ — แก้เป็นเนื้อหาจริงได้) | F26: ดำเนินการ ระบุ Emerging Risk เป็นข้อมูลน ตามแผนในเดือนก.พ. (สรุปย่อ — แก้เป็นเนื้อหาจริงได้) | G26: ดำเนินการ ระบุ Emerging Risk เป็นข้อมูลน ตามแผนในเดือนมี.ค. (สรุปย่อ — แก้เป็นเนื้อหาจริงได้) | H26: ดำเนินการ ระบุ Emerging Risk เป็นข้อมูลน ตามแผนในเดือนเม.ย. (สรุปย่อ — แก้เป็นเนื้อหาจริงได้) | I26: ดำเนินการ ระบุ Emerging Risk เป็นข้อมูลน ตามแผนในเดือนพ.ค. (สรุปย่อ — แก้เป็นเนื้อหาจริงได้) | J26: ดำเนินการ ระบุ Emerging Risk เป็นข้อมูลน ตามแผนในเดือนมิ.ย. (สรุปย่อ — แก้เป็นเนื้อหาจริงได้)
A27: M_2.3.3 | B27: 2.3.3 | C27: ระบุ Intelligent Risk ที่อาจส่งผลต่อบรรลุเป้าหมายในแต่ละตำแหน่งเชิงยุทธศาสตร์ขององค์กร | D27: 2. | H27: ดำเนินการ ระบุ Intelligent Risk ที่อาจส่ ตามแผนในเดือนเม.ย. (สรุปย่อ — แก้เป็นเนื้อหาจริงได้) | I27: ดำเนินการ ระบุ Intelligent Risk ที่อาจส่ ตามแผนในเดือนพ.ค. (สรุปย่อ — แก้เป็นเนื้อหาจริงได้) | J27: ดำเนินการ ระบุ Intelligent Risk ที่อาจส่ ตามแผนในเดือนมิ.ย. (สรุปย่อ — แก้เป็นเนื้อหาจริงได้)
A28: M_2.3.4 | B28: 2.3.4 | C28: ระบุและวิเคราะห์ความเสี่ยงที่อาจส่งผลต่อการบรรลุวัตถุประสงค์เชิงยุทธศาสตร์ (SO) | D28: 2. | H28: ดำเนินการ ระบุและวิเคราะห์ความเสี่ยงที่อ ตามแผนในเดือนเม.ย. (สรุปย่อ — แก้เป็นเนื้อหาจริงได้) | I28: ดำเนินการ ระบุและวิเคราะห์ความเสี่ยงที่อ ตามแผนในเดือนพ.ค. (สรุปย่อ — แก้เป็นเนื้อหาจริงได้) | J28: ดำเนินการ ระบุและวิเคราะห์ความเสี่ยงที่อ ตามแผนในเดือนมิ.ย. (สรุปย่อ — แก้เป็นเนื้อหาจริงได้)
A29: M_2.3.5 | B29: 2.3.5 | C29: ทบทวนแบบฟอร์มและเกณฑ์การประเมินความเสี่ยงและ ประสิทธิผลของการควบคุมของแผน AP และแผนแม่บทที่เกี่ยวข้อง | D29: 2. | I29: ดำเนินการ ทบทวนแบบฟอร์มและเกณฑ์การประเมิ ตามแผนในเดือนพ.ค. (สรุปย่อ — แก้เป็นเนื้อหาจริงได้) | J29: ดำเนินการ ทบทวนแบบฟอร์มและเกณฑ์การประเมิ ตามแผนในเดือนมิ.ย. (สรุปย่อ — แก้เป็นเนื้อหาจริงได้)
A30: M_2.3.6 | B30: 2.3.6 | C30: สื่อสารแบบฟอร์มการประเมินความเสี่ยง และหลักเกณฑ์การประเมินความเพียงพอของการควบคุมภายใน | D30: 2. | J30: ดำเนินการ สื่อสารแบบฟอร์มการประเมินความเ ตามแผนในเดือนมิ.ย. (สรุปย่อ — แก้เป็นเนื้อหาจริงได้)
A31: M_2.3.7 | B31: 2.3.7 | C31: ติดตามการวิเคราะห์ ระบุ และประเมินความเสี่ยงของแผนปฏิบัติการ และแผนแม่บทที่เกี่ยวข้อง พร้อมกำหนดมาตรการจัดการความเสี่ยง | D31: 2. | J31: ดำเนินการ ติดตามการวิเคราะห์ ระบุ และประ ตามแผนในเดือนมิ.ย. (สรุปย่อ — แก้เป็นเนื้อหาจริงได้)
A32: M_2.4.1 | B32: 2.4.1 | C32: รวบรวม/วิเคราะห์ข้อมูลความเสี่ยง การควบคุม และนำเข้าใน Risk Inventory พร้อมทบทวนเกณฑ์ประเมินการควบคุม | D32: 2. | E32: ดำเนินการ รวบรวม/วิเคราะห์ข้อมูลความเสี่ ตามแผนในเดือนม.ค. (สรุปย่อ — แก้เป็นเนื้อหาจริงได้) | F32: ดำเนินการ รวบรวม/วิเคราะห์ข้อมูลความเสี่ ตามแผนในเดือนก.พ. (สรุปย่อ — แก้เป็นเนื้อหาจริงได้) | G32: ดำเนินการ รวบรวม/วิเคราะห์ข้อมูลความเสี่ ตามแผนในเดือนมี.ค. (สรุปย่อ — แก้เป็นเนื้อหาจริงได้) | H32: ดำเนินการ รวบรวม/วิเคราะห์ข้อมูลความเสี่ ตามแผนในเดือนเม.ย. (สรุปย่อ — แก้เป็นเนื้อหาจริงได้) | I32: ดำเนินการ รวบรวม/วิเคราะห์ข้อมูลความเสี่ ตามแผนในเดือนพ.ค. (สรุปย่อ — แก้เป็นเนื้อหาจริงได้) | J32: ดำเนินการ รวบรวม/วิเคราะห์ข้อมูลความเสี่ ตามแผนในเดือนมิ.ย. (สรุปย่อ — แก้เป็นเนื้อหาจริงได้)
A33: M_2.4.2 | B33: 2.4.2 | C33: คัดเลือกปัจจัยเสี่ยงระดับองค์กร พร้อมวิเคราะห์ Leading / Lagging Indicator ของแต่ละความเสี่ยง | D33: 2. | J33: ดำเนินการ คัดเลือกปัจจัยเสี่ยงระดับองค์ก ตามแผนในเดือนมิ.ย. (สรุปย่อ — แก้เป็นเนื้อหาจริงได้)
A34: M_2.4.3 | B34: 2.4.3 | C34: จัดให้มีการประเมินความเสี่ยง และสื่อสารความเสี่ยงต่อผู้รับผิดชอบ | D34: 2.
A35: M_2.4.4 | B35: 2.4.4 | C35: พิจารณาและคัดเลือกวิธีการจัดการความเสี่ยง พร้อมทั้ง วิเคราะห์และจัดทำ Risk Correlation Map/Portfolio View of Risk | D35: 2.
A36: M_2.4.5 | B36: 2.4.5 | C36: จัดทำแผนบริหารความเสี่ยง และทบทวนแผนบริหารความเสี่ยงของปีถัดไป | D36: 2.
A37: M_2.4.6 | B37: 2.4.6 | C37: ติดตามและรายงานผลการบริหารความเสี่ยงและการควบคุมของความเสี่ยงปีปัจจุบัน | D37: 2. | E37: ดำเนินการ ติดตามและรายงานผลการบริหารความ ตามแผนในเดือนม.ค. (สรุปย่อ — แก้เป็นเนื้อหาจริงได้) | F37: ดำเนินการ ติดตามและรายงานผลการบริหารความ ตามแผนในเดือนก.พ. (สรุปย่อ — แก้เป็นเนื้อหาจริงได้) | G37: ดำเนินการ ติดตามและรายงานผลการบริหารความ ตามแผนในเดือนมี.ค. (สรุปย่อ — แก้เป็นเนื้อหาจริงได้) | H37: ดำเนินการ ติดตามและรายงานผลการบริหารความ ตามแผนในเดือนเม.ย. (สรุปย่อ — แก้เป็นเนื้อหาจริงได้) | I37: ดำเนินการ ติดตามและรายงานผลการบริหารความ ตามแผนในเดือนพ.ค. (สรุปย่อ — แก้เป็นเนื้อหาจริงได้) | J37: ดำเนินการ ติดตามและรายงานผลการบริหารความ ตามแผนในเดือนมิ.ย. (สรุปย่อ — แก้เป็นเนื้อหาจริงได้)
A38: M_2.4.7 | B38: 2.4.7 | C38: พัฒนาระบบเทคโนโลยีดิจิทัลเพื่อสนับสนุนกระบวนการบริหารความเสี่ยง และระบบเตือนภัยล่วงหน้า | D38: 2. | E38: ดำเนินการ พัฒนาระบบเทคโนโลยีดิจิทัลเพื่อ ตามแผนในเดือนม.ค. (สรุปย่อ — แก้เป็นเนื้อหาจริงได้) | F38: ดำเนินการ พัฒนาระบบเทคโนโลยีดิจิทัลเพื่อ ตามแผนในเดือนก.พ. (สรุปย่อ — แก้เป็นเนื้อหาจริงได้) | G38: ดำเนินการ พัฒนาระบบเทคโนโลยีดิจิทัลเพื่อ ตามแผนในเดือนมี.ค. (สรุปย่อ — แก้เป็นเนื้อหาจริงได้) | H38: ดำเนินการ พัฒนาระบบเทคโนโลยีดิจิทัลเพื่อ ตามแผนในเดือนเม.ย. (สรุปย่อ — แก้เป็นเนื้อหาจริงได้) | I38: ดำเนินการ พัฒนาระบบเทคโนโลยีดิจิทัลเพื่อ ตามแผนในเดือนพ.ค. (สรุปย่อ — แก้เป็นเนื้อหาจริงได้) | J38: ดำเนินการ พัฒนาระบบเทคโนโลยีดิจิทัลเพื่อ ตามแผนในเดือนมิ.ย. (สรุปย่อ — แก้เป็นเนื้อหาจริงได้)
A39: M_2.4.8 | B39: 2.4.8 | C39: ทบทวน ประเมินประสิทธิผล และปรับปรุงกระบวนการบริหารความเสี่ยง | D39: 2.
A40: M_2.5.1 | B40: 2.5.1 | C40: วิเคราะห์ผลกระทบทางธุรกิจ ประเมินความเสี่ยง ทบทวนกลยุทธ์ และ BCP | D40: 2. | E40: ดำเนินการ วิเคราะห์ผลกระทบทางธุรกิจ ประเ ตามแผนในเดือนม.ค. (สรุปย่อ — แก้เป็นเนื้อหาจริงได้) | F40: ดำเนินการ วิเคราะห์ผลกระทบทางธุรกิจ ประเ ตามแผนในเดือนก.พ. (สรุปย่อ — แก้เป็นเนื้อหาจริงได้) | G40: ดำเนินการ วิเคราะห์ผลกระทบทางธุรกิจ ประเ ตามแผนในเดือนมี.ค. (สรุปย่อ — แก้เป็นเนื้อหาจริงได้) | H40: ดำเนินการ วิเคราะห์ผลกระทบทางธุรกิจ ประเ ตามแผนในเดือนเม.ย. (สรุปย่อ — แก้เป็นเนื้อหาจริงได้) | I40: ดำเนินการ วิเคราะห์ผลกระทบทางธุรกิจ ประเ ตามแผนในเดือนพ.ค. (สรุปย่อ — แก้เป็นเนื้อหาจริงได้) | J40: ดำเนินการ วิเคราะห์ผลกระทบทางธุรกิจ ประเ ตามแผนในเดือนมิ.ย. (สรุปย่อ — แก้เป็นเนื้อหาจริงได้)
...

Sheet รายงานประจำเดือน
A1: เดือน | B1: รายงานภาพรวมประจำเดือน
A2: ม.ค. | B2: ภาพรวมการดำเนินงานตามแผนบริหารความเสี่ยงประจำเดือนม.ค. — (แก้เป็นเนื้อหาสรุปจริง)
A3: ก.พ. | B3: ภาพรวมการดำเนินงานตามแผนบริหารความเสี่ยงประจำเดือนก.พ. — (แก้เป็นเนื้อหาสรุปจริง)
A4: มี.ค. | B4: ภาพรวมการดำเนินงานตามแผนบริหารความเสี่ยงประจำเดือนมี.ค. — (แก้เป็นเนื้อหาสรุปจริง)
A5: เม.ย. | B5: ภาพรวมการดำเนินงานตามแผนบริหารความเสี่ยงประจำเดือนเม.ย. — (แก้เป็นเนื้อหาสรุปจริง)
A6: พ.ค. | B6: ภาพรวมการดำเนินงานตามแผนบริหารความเสี่ยงประจำเดือนพ.ค. — (แก้เป็นเนื้อหาสรุปจริง)
A7: มิ.ย. | B7: ภาพรวมการดำเนินงานตามแผนบริหารความเสี่ยงประจำเดือนมิ.ย. — (แก้เป็นเนื้อหาสรุปจริง)
A8: ก.ค.
A9: ส.ค.
A10: ก.ย.
A11: ต.ค.
A12: พ.ย.
A13: ธ.ค.

Sheet สรุปเป้าหมายตามแผน
A1: แผนหลัก | B1: รหัสแผน | C1: ม.ค. | D1: ก.พ. | E1: มี.ค. | F1: เม.ย. | G1: พ.ค. | H1: มิ.ย. | I1: ก.ค. | J1: ส.ค. | K1: ก.ย. | L1: ต.ค. | M1: พ.ย. | N1: ธ.ค.
A2: 1. แผนปรับปรุงการบูรณาการการกำกับดูแลกิจการที่ดี การบริหารความเสี่ยง และการปฏิบัติตามกฎ ระเบียบ (GRC) | B2: 1. | C2: =IFERROR(SUMPRODUCT((บันทึกผล!$B$2:$B$49=$B2)*บันทึกผล!$AH$2:$AH$49*N(บันทึกผล!G$2:G$49))/SUMPRODUCT((บันทึกผล!$B$2:$B$49=$B2)*บันทึกผล!$AH$2:$AH$49),"") | D2: =IFERROR(SUMPRODUCT((บันทึกผล!$B$2:$B$49=$B2)*บันทึกผล!$AH$2:$AH$49*N(บันทึกผล!H$2:H$49))/SUMPRODUCT((บันทึกผล!$B$2:$B$49=$B2)*บันทึกผล!$AH$2:$AH$49),"") | E2: =IFERROR(SUMPRODUCT((บันทึกผล!$B$2:$B$49=$B2)*บันทึกผล!$AH$2:$AH$49*N(บันทึกผล!I$2:I$49))/SUMPRODUCT((บันทึกผล!$B$2:$B$49=$B2)*บันทึกผล!$AH$2:$AH$49),"") | F2: =IFERROR(SUMPRODUCT((บันทึกผล!$B$2:$B$49=$B2)*บันทึกผล!$AH$2:$AH$49*N(บันทึกผล!J$2:J$49))/SUMPRODUCT((บันทึกผล!$B$2:$B$49=$B2)*บันทึกผล!$AH$2:$AH$49),"") | G2: =IFERROR(SUMPRODUCT((บันทึกผล!$B$2:$B$49=$B2)*บันทึกผล!$AH$2:$AH$49*N(บันทึกผล!K$2:K$49))/SUMPRODUCT((บันทึกผล!$B$2:$B$49=$B2)*บันทึกผล!$AH$2:$AH$49),"") | H2: =IFERROR(SUMPRODUCT((บันทึกผล!$B$2:$B$49=$B2)*บันทึกผล!$AH$2:$AH$49*N(บันทึกผล!L$2:L$49))/SUMPRODUCT((บันทึกผล!$B$2:$B$49=$B2)*บันทึกผล!$AH$2:$AH$49),"") | I2: =IFERROR(SUMPRODUCT((บันทึกผล!$B$2:$B$49=$B2)*บันทึกผล!$AH$2:$AH$49*N(บันทึกผล!M$2:M$49))/SUMPRODUCT((บันทึกผล!$B$2:$B$49=$B2)*บันทึกผล!$AH$2:$AH$49),"") | J2: =IFERROR(SUMPRODUCT((บันทึกผล!$B$2:$B$49=$B2)*บันทึกผล!$AH$2:$AH$49*N(บันทึกผล!N$2:N$49))/SUMPRODUCT((บันทึกผล!$B$2:$B$49=$B2)*บันทึกผล!$AH$2:$AH$49),"") | ... N2: =IFERROR(SUMPRODUCT((บันทึกผล!$B$2:$B$49=$B2)*บันทึกผล!$AH$2:$AH$49*N(บันทึกผล!R$2:R$49))/SUMPRODUCT((บันทึกผล!$B$2:$B$49=$B2)*บันทึกผล!$AH$2:$AH$49),"")
A3: 2. แผนปฏิบัติการบริหารความเสี่ยง และการบริหารความต่อเนื่องทางธุรกิจ | B3: 2. | C3: =IFERROR(SUMPRODUCT((บันทึกผล!$B$2:$B$49=$B3)*บันทึกผล!$AH$2:$AH$49*N(บันทึกผล!G$2:G$49))/SUMPRODUCT((บันทึกผล!$B$2:$B$49=$B3)*บันทึกผล!$AH$2:$AH$49),"") | D3: =IFERROR(SUMPRODUCT((บันทึกผล!$B$2:$B$49=$B3)*บันทึกผล!$AH$2:$AH$49*N(บันทึกผล!H$2:H$49))/SUMPRODUCT((บันทึกผล!$B$2:$B$49=$B3)*บันทึกผล!$AH$2:$AH$49),"") | E3: =IFERROR(SUMPRODUCT((บันทึกผล!$B$2:$B$49=$B3)*บันทึกผล!$AH$2:$AH$49*N(บันทึกผล!I$2:I$49))/SUMPRODUCT((บันทึกผล!$B$2:$B$49=$B3)*บันทึกผล!$AH$2:$AH$49),"") | F3: =IFERROR(SUMPRODUCT((บันทึกผล!$B$2:$B$49=$B3)*บันทึกผล!$AH$2:$AH$49*N(บันทึกผล!J$2:J$49))/SUMPRODUCT((บันทึกผล!$B$2:$B$49=$B3)*บันทึกผล!$AH$2:$AH$49),"") | G3: =IFERROR(SUMPRODUCT((บันทึกผล!$B$2:$B$49=$B3)*บันทึกผล!$AH$2:$AH$49*N(บันทึกผล!K$2:K$49))/SUMPRODUCT((บันทึกผล!$B$2:$B$49=$B3)*บันทึกผล!$AH$2:$AH$49),"") | H3: =IFERROR(SUMPRODUCT((บันทึกผล!$B$2:$B$49=$B3)*บันทึกผล!$AH$2:$AH$49*N(บันทึกผล!L$2:L$49))/SUMPRODUCT((บันทึกผล!$B$2:$B$49=$B3)*บันทึกผล!$AH$2:$AH$49),"") | I3: =IFERROR(SUMPRODUCT((บันทึกผล!$B$2:$B$49=$B3)*บันทึกผล!$AH$2:$AH$49*N(บันทึกผล!M$2:M$49))/SUMPRODUCT((บันทึกผล!$B$2:$B$49=$B3)*บันทึกผล!$AH$2:$AH$49),"") | J3: =IFERROR(SUMPRODUCT((บันทึกผล!$B$2:$B$49=$B3)*บันทึกผล!$AH$2:$AH$49*N(บันทึกผล!N$2:N$49))/SUMPRODUCT((บันทึกผล!$B$2:$B$49=$B3)*บันทึกผล!$AH$2:$AH$49),"") | ... N3: =IFERROR(SUMPRODUCT((บันทึกผล!$B$2:$B$49=$B3)*บันทึกผล!$AH$2:$AH$49*N(บันทึกผล!R$2:R$49))/SUMPRODUCT((บันทึกผล!$B$2:$B$49=$B3)*บันทึกผล!$AH$2:$AH$49),"")
A4: 3. แผนปรับปรุงองค์กรด้าน RM & IC ปี 2569 | B4: 3. | C4: =IFERROR(SUMPRODUCT((บันทึกผล!$B$2:$B$49=$B4)*บันทึกผล!$AH$2:$AH$49*N(บันทึกผล!G$2:G$49))/SUMPRODUCT((บันทึกผล!$B$2:$B$49=$B4)*บันทึกผล!$AH$2:$AH$49),"") | D4: =IFERROR(SUMPRODUCT((บันทึกผล!$B$2:$B$49=$B4)*บันทึกผล!$AH$2:$AH$49*N(บันทึกผล!H$2:H$49))/SUMPRODUCT((บันทึกผล!$B$2:$B$49=$B4)*บันทึกผล!$AH$2:$AH$49),"") | E4: =IFERROR(SUMPRODUCT((บันทึกผล!$B$2:$B$49=$B4)*บันทึกผล!$AH$2:$AH$49*N(บันทึกผล!I$2:I$49))/SUMPRODUCT((บันทึกผล!$B$2:$B$49=$B4)*บันทึกผล!$AH$2:$AH$49),"") | F4: =IFERROR(SUMPRODUCT((บันทึกผล!$B$2:$B$49=$B4)*บันทึกผล!$AH$2:$AH$49*N(บันทึกผล!J$2:J$49))/SUMPRODUCT((บันทึกผล!$B$2:$B$49=$B4)*บันทึกผล!$AH$2:$AH$49),"") | G4: =IFERROR(SUMPRODUCT((บันทึกผล!$B$2:$B$49=$B4)*บันทึกผล!$AH$2:$AH$49*N(บันทึกผล!K$2:K$49))/SUMPRODUCT((บันทึกผล!$B$2:$B$49=$B4)*บันทึกผล!$AH$2:$AH$49),"") | H4: =IFERROR(SUMPRODUCT((บันทึกผล!$B$2:$B$49=$B4)*บันทึกผล!$AH$2:$AH$49*N(บันทึกผล!L$2:L$49))/SUMPRODUCT((บันทึกผล!$B$2:$B$49=$B4)*บันทึกผล!$AH$2:$AH$49),"") | I4: =IFERROR(SUMPRODUCT((บันทึกผล!$B$2:$B$49=$B4)*บันทึกผล!$AH$2:$AH$49*N(บันทึกผล!M$2:M$49))/SUMPRODUCT((บันทึกผล!$B$2:$B$49=$B4)*บันทึกผล!$AH$2:$AH$49),"") | J4: =IFERROR(SUMPRODUCT((บันทึกผล!$B$2:$B$49=$B4)*บันทึกผล!$AH$2:$AH$49*N(บันทึกผล!N$2:N$49))/SUMPRODUCT((บันทึกผล!$B$2:$B$49=$B4)*บันทึกผล!$AH$2:$AH$49),"") | ... N4: =IFERROR(SUMPRODUCT((บันทึกผล!$B$2:$B$49=$B4)*บันทึกผล!$AH$2:$AH$49*N(บันทึกผล!R$2:R$49))/SUMPRODUCT((บันทึกผล!$B$2:$B$49=$B4)*บันทึกผล!$AH$2:$AH$49),"")
A5: รวมทั้งหมด (ถ่วงน้ำหนักทุกกิจกรรม) | B5: * | C5: =IFERROR(SUMPRODUCT(บันทึกผล!$AH$2:$AH$49*N(บันทึกผล!G$2:G$49))/SUMPRODUCT(บันทึกผล!$AH$2:$AH$49),"") | D5: =IFERROR(SUMPRODUCT(บันทึกผล!$AH$2:$AH$49*N(บันทึกผล!H$2:H$49))/SUMPRODUCT(บันทึกผล!$AH$2:$AH$49),"") | E5: =IFERROR(SUMPRODUCT(บันทึกผล!$AH$2:$AH$49*N(บันทึกผล!I$2:I$49))/SUMPRODUCT(บันทึกผล!$AH$2:$AH$49),"") | F5: =IFERROR(SUMPRODUCT(บันทึกผล!$AH$2:$AH$49*N(บันทึกผล!J$2:J$49))/SUMPRODUCT(บันทึกผล!$AH$2:$AH$49),"") | G5: =IFERROR(SUMPRODUCT(บันทึกผล!$AH$2:$AH$49*N(บันทึกผล!K$2:K$49))/SUMPRODUCT(บันทึกผล!$AH$2:$AH$49),"") | H5: =IFERROR(SUMPRODUCT(บันทึกผล!$AH$2:$AH$49*N(บันทึกผล!L$2:L$49))/SUMPRODUCT(บันทึกผล!$AH$2:$AH$49),"") | I5: =IFERROR(SUMPRODUCT(บันทึกผล!$AH$2:$AH$49*N(บันทึกผล!M$2:M$49))/SUMPRODUCT(บันทึกผล!$AH$2:$AH$49),"") | J5: =IFERROR(SUMPRODUCT(บันทึกผล!$AH$2:$AH$49*N(บันทึกผล!N$2:N$49))/SUMPRODUCT(บันทึกผล!$AH$2:$AH$49),"") | ... N5: =IFERROR(SUMPRODUCT(บันทึกผล!$AH$2:$AH$49*N(บันทึกผล!R$2:R$49))/SUMPRODUCT(บันทึกผล!$AH$2:$AH$49),"")
